Workbook

Sheet Publicação
B2: ESTADO DE MINAS GERAIS – PODER EXECUTIVO
B3: RELATÓRIO DE GESTÃO FISCAL
B4: DEMONSTRATIVO DA DESPESA COM PESSOAL
B5: ORÇAMENTO FISCAL
B6: JANEIRO A DEZEMBRO/2025
B8: RGF - ANEXO 1 (LRF. art. 55, inciso I. alínea "a") - Portaria 699/23 STN | J8: Em Reais
B9: DESPESA COM PESSOAL | C9: Jan/25 | D9: Fev/25 | E9: Mar/25 | F9: Abr/25 | G9: Mai/25 | H9: Jun/25 | I9: Jul/25 | J9: Ago/25
B10: DESPESA BRUTA COM PESSOAL (I) | C10: =C11+C14+C17+C18 -> 5.1423353e+09 | D10: =D11+D14+D17+D18 -> 4.6915752e+09 | E10: =E11+E14+E17+E18 -> 4.8835995e+09 | F10: =F11+F14+F17+F18 -> 4.9840156e+09 | G10: 5.0079464e+09 | H10: 4.9938442e+09 | I10: 5.1389955e+09 | J10: 5.0301473e+09 | S10: =SUM(C10:I10)+D30+E30+F30+G30-H30 -> -5.0301473e+09 | T10: =H30+I30-J30 -> 0
B11: Pessoal Ativo | C11: 3.6422063e+09 | D11: =D12+D13 -> 1.7885156e+09 | E11: =E12+E13 -> 2.6839694e+09 | F11: =F12+F13 -> 2.7348032e+09 | G11: 2.7857615e+09 | H11: 2.6992833e+09 | I11: 2.8702463e+09 | J11: 2.6874502e+09 | S11: =SUM(C11:I11)+D31+E31+F31+G31-H31 -> -2.6874502e+09 | T11: =H31+I31-J31 -> 0
B12: Vencimentos, Vantagens e Outras Despesas Variáveis | C12: 2.7411992e+09 | D12: 1.2868982e+09 | E12: 1.9751016e+09 | F12: 2.0206544e+09 | G12: 2.012716e+09 | H12: 1.9970632e+09 | I12: 2.1266656e+09 | J12: 2.0121768e+09 | S12: =SUM(C12:I12)+D32+E32+F32+G32-H32 -> -2.0121768e+09 | T12: =H32+I32-J32 -> 0
B13: Obrigações Patronais | C13: 9.0100704e+08 | D13: 5.0161738e+08 | E13: 7.0886772e+08 | F13: 7.1414881e+08 | G13: 7.7304547e+08 | H13: 7.0222009e+08 | I13: 7.4358068e+08 | J13: 6.7527342e+08 | S13: =SUM(C13:I13)+D33+E33+F33+G33-H33 -> -6.7527342e+08 | T13: =H33+I33-J33 -> 0
B14: Pessoal Inativo e Pensionistas | C14: =SUM(C15:C16) -> 1.500129e+09 | D14: =SUM(D15:D16) -> 2.9030596e+09 | E14: =SUM(E15:E16) -> 2.1996071e+09 | F14: =SUM(F15:F16) -> 2.214173e+09 | G14: 2.2065635e+09 | H14: 2.314318e+09 | I14: 2.2890086e+09 | J14: 2.3043447e+09 | S14: =SUM(C14:I14)+D34+E34+F34+G34-H34 -> -2.3043447e+09 | T14: =H34+I34-J34 -> 0
B15: Aposentadorias, Reserva e Reformas | C15: 1.1260288e+09 | D15: 2.5031605e+09 | E15: 1.815649e+09 | F15: 1.8267881e+09 | G15: 1.8226467e+09 | H15: 1.9302268e+09 | I15: 1.8995775e+09 | J15: 1.9072765e+09 | S15: =SUM(C15:I15)+D35+E35+F35+G35-H35 -> -1.9072765e+09 | T15: =H35+I35-J35 -> 0
B16: Pensões | C16: 3.7410016e+08 | D16: 3.9989904e+08 | E16: 3.8395817e+08 | F16: 3.8738495e+08 | G16: 3.8391682e+08 | H16: 3.8409123e+08 | I16: 3.8943111e+08 | J16: 3.9706814e+08 | S16: =SUM(C16:I16)+D36+E36+F36+G36-H36 -> -3.9706814e+08 | T16: =H36+I36-J36 -> 0
B17: Outras Despesas de Pessoal Decorrentes de Contratos de Terceirização ou de Contratação de Forma Indireta (§ 1º do art. 18 da LRF) | C17: 0 | D17: 0 | F17: 0 | S17: =SUM(C17:I17)+D37+E37+F37+G37-H37 -> 0 | T17: =H37+I37-J37 -> 0
B18: Despesa com Pessoal não Executada Orçamentariamente | C18: 0 | D18: 0 | E18: 23029.97 | F18: 35039362 | G18: 15621426 | H18: -19757079 | I18: -20259400 | J18: 38352468 | S18: =SUM(C18:I18)+D38+E38+F38+G38-H38 -> -38352468 | T18: =H38+I38-J38 -> 0
B19: DESPESAS NÃO COMPUTADAS (II) (§ 1º do art. 19 da LRF) | C19: =SUM(C20:C26) -> 6.7952037e+08 | D19: =SUM(D20:D26) -> 1.0026006e+09 | E19: =SUM(E20:E26) -> 8.0737208e+08 | F19: =SUM(F20:F26) -> 8.566579e+08 | G19: 8.7817804e+08 | H19: 8.8687702e+08 | I19: 8.7385787e+08 | J19: 8.6940638e+08 | S19: =SUM(C19:I19)+D39+E39+F39+G39-H39 -> -8.6940638e+08 | T19: =H39+I39-J39 -> 0
B20: Indenizações por Demissão e Incentivos à Demissão Voluntária | C20: 1984726.2 | D20: 2244912.2 | E20: 2122054 | F20: 1553277.4 | G20: 1368792.1 | H20: 2451823.1 | I20: 2391006.8 | J20: 482313.95 | S20: =SUM(C20:I20)+D40+E40+F40+G40-H40 -> -482313.95 | T20: =H40+I40-J40 -> 0
B21: Decorrentes de Decisão Judicial de Período Anterior ao da Apuração | C21: 5135554.3 | D21: 48028279 | E21: 53015036 | F21: 31679698 | G21: 24434207 | H21: 57125609 | I21: 16034527 | J21: 6576529.7 | S21: =SUM(C21:I21)+D41+E41+F41+G41-H41 -> -6576529.7 | T21: =H41+I41-J41 -> 0
B22: Despesas de Exercícios Anteriores de Período Anterior ao da Apuração | C22: 18893960 | D22: 9409431.3 | E22: 4193813.6 | F22: 3493284.5 | G22: 9278263.4 | H22: 20786745 | I22: -2585355.6 | J22: 11251207 | S22: =SUM(C22:I22)+D42+E42+F42+G42-H42 -> -11251207 | T22: =H42+I42-J42 -> 0
B23: Inativos e Pensionistas com Recursos Vinculados | C23: 6.5135895e+08 | D23: 9.4053523e+08 | E23: 7.4546709e+08 | F23: 8.1764179e+08 | G23: 8.4089375e+08 | H23: 8.0426838e+08 | I23: 8.5570113e+08 | J23: 8.4869337e+08 | S23: =SUM(C23:I23)+D43+E43+F43+G43-H43 -> -8.4869337e+08 | T23: =H43+I43-J43 -> 0
B24: Agentes Comunitários de Saúde e de Combate às Endemias com Recursos Vinculados (CF, art.198, § 11) | C24: 0 | D24: 0 | E24: 0 | F24: 0 | S24: =SUM(C24:I24)+D44+E44+F44+G44-H44 -> 0 | T24: =H44+I44-J44 -> 0
B25: Parcela dedutível referente ao piso salarial do Enfermeiro, Técnico de Enfermagem, Auxiliar de Enfermagem e Parteira (ADCT, art. 38, §2º) ¹ | C25: =2683978.42*0.8 -> 2147182.7 | D25: =2978411.33*0.8 -> 2382729.1 | E25: =3217606.43*0.8 -> 2574085.1 | F25: =2862311.96*0.8 -> 2289849.6 | G25: 2203034.6 | H25: 2244464.7 | I25: 2316564.2 | J25: 2402954.9 | S25: =SUM(C25:I25)+D45+E45+F45+G45-H45 -> -2402954.9 | T25: =H45+I45-J45 -> 0
B26: Outras Deduções Constitucionais ou Legais | C26: 0 | D26: 0 | F26: 0 | S26: =SUM(C26:I26)+D46+E46+F46+G46-H46 -> 0 | T26: =H46+I46-J46 -> 0
B27: DESPESA LÍQUIDA COM PESSOAL (III) = (I - II) | C27: =C10-C19 -> 4.4628149e+09 | D27: =D10-D19 -> 3.6889746e+09 | E27: =E10-E19 -> 4.0762274e+09 | F27: =F10-F19 -> 4.1273577e+09 | G27: 4129768343 | H27: 4.1069672e+09 | I27: 4.2651377e+09 | J27: 4.160741e+09 | S27: =SUM(C27:I27)+D47+E47+F47+G47-H47 -> -4.160741e+09 | T27: =H47+I47-J47 -> 0
B29: DESPESA COM PESSOAL | D29: Set/25 | E29: Out/25 | F29: Nov/25 | G29: Dez/25 | H29: Últimos 12 Meses (a) | I29: Inscritas em Restos a Pagar Não Processados (b) | J29: Despesa Executada (a + b)
B30: DESPESA BRUTA COM PESSOAL (I) | D30: =D31+D34+D37+D38 -> 5.1453318e+09 | E30: =E31+E34+E37+E38 -> 5.0459924e+09 | F30: =F31+F34+F37+F38 -> 6.4269211e+09 | G30: =G31+G34+G37+G38 -> 9.0000201e+09 | H30: =H31+H34+H37+H38 -> 6.5490724e+10 | I30: =I31+I34+I37+I38 -> 1837811.9 | J30: =J31+J34+J37+J38 -> 6.5492562e+10 | L30: =SUM(C10:J10)+D30+E30+F30+G30-H30 -> 0 | M30: =H30+I30-J30 -> 0
B31: Pessoal Ativo | D31: =SUM(D32:D33) -> 2.6274983e+09 | E31: =SUM(E32:E33) -> 2.9386391e+09 | F31: =SUM(F32:F33) -> 3.5226226e+09 | G31: =SUM(G32:G33) -> 5.2257391e+09 | H31: =SUM(C11:J11)+D31+E31+F31+G31 -> 3.6206735e+10 | I31: =SUM(I32:I33) -> 1837811.9 | J31: =H31+I31 -> 3.6208573e+10 | L31: =SUM(C11:J11)+D31+E31+F31+G31-H31 -> 0 | M31: =H31+I31-J31 -> 0
B32: Vencimentos, Vantagens e Outras Despesas Variáveis | D32: =[1]Query_Total!K13 -> 1.9579241e+09 | E32: =[1]Query_Total!L13 -> 2.1269111e+09 | F32: =[1]Query_Total!M13 -> 2.5947719e+09 | G32: =[1]Query_Total!N13 -> 3.7958527e+09 | H32: =SUM(C12:J12)+D32+E32+F32+G32 -> 2.6647935e+10 | I32: =[1]Pessoal_3ºQuadrimestre!D13 -> 1722535.8 | J32: =H32+I32 -> 2.6649657e+10 | L32: =SUM(C12:J12)+D32+E32+F32+G32-H32 -> 0 | M32: =H32+I32-J32 -> 0
B33: Obrigações Patronais | D33: =[1]Query_Total!K29 -> 6.6957426e+08 | E33: =[1]Query_Total!L29 -> 8.1172793e+08 | F33: =[1]Query_Total!M29 -> 9.2785066e+08 | G33: =[1]Query_Total!N29 -> 1.4298865e+09 | H33: =SUM(C13:J13)+D33+E33+F33+G33 -> 9.5587999e+09 | I33: =[1]Pessoal_3ºQuadrimestre!D27 -> 115276.15 | J33: =H33+I33 -> 9.5589152e+09 | L33: =SUM(C13:J13)+D33+E33+F33+G33-H33 -> 0 | M33: =H33+I33-J33 -> 0
B34: Pessoal Inativo e Pensionistas | D34: =SUM(D35:D36) -> 2.3147416e+09 | E34: =SUM(E35:E36) -> 2.2894027e+09 | F34: =SUM(F35:F36) -> 2.9568515e+09 | G34: =SUM(G35:G36) -> 3.7917903e+09 | H34: =SUM(C14:J14)+D34+E34+F34+G34 -> 2.928399e+10 | I34: =SUM(I35:I36) -> 0 | J34: =H34+I34 -> 2.928399e+10 | L34: =SUM(C14:J14)+D34+E34+F34+G34-H34 -> 0 | M34: =H34+I34-J34 -> 0
B35: Aposentadorias, Reserva e Reformas | D35: =[1]Query_Total!K39 -> 1.9093191e+09 | E35: =[1]Query_Total!L39 -> 1.892548e+09 | F35: =[1]Query_Total!M39 -> 2.5689937e+09 | G35: =[1]Query_Total!N39 -> 3.0347138e+09 | H35: =SUM(C15:J15)+D35+E35+F35+G35 -> 2.4236928e+10 | J35: =H35+I35 -> 2.4236928e+10 | L35: =SUM(C15:J15)+D35+E35+F35+G35-H35 -> 0 | M35: =H35+I35-J35 -> 0
B36: Pensões | D36: =[1]Query_Total!K43 -> 4.0542254e+08 | E36: =[1]Query_Total!L43 -> 3.9685465e+08 | F36: =[1]Query_Total!M43 -> 3.8785775e+08 | G36: =[1]Query_Total!N43 -> 7.5707651e+08 | H36: =SUM(C16:J16)+D36+E36+F36+G36 -> 5.0470611e+09 | I36: 0 | J36: =H36+I36 -> 5.0470611e+09 | L36: =SUM(C16:J16)+D36+E36+F36+G36-H36 -> 0 | M36: =H36+I36-J36 -> 0
B37: Outras Despesas de Pessoal Decorrentes de Contratos de Terceirização ou de Contratação de Forma Indireta (§ 1º do art. 18 da LRF) | D37: =[1]Query_Total!K48 -> 0 | E37: =[1]Query_Total!L48 -> 0 | F37: =[1]Query_Total!M48 -> 0 | G37: =[1]Query_Total!N48 -> 0 | H37: =SUM(C17:J17)+D37+E37+F37+G37 -> 0 | I37: 0 | J37: =H37+I37 -> 0 | L37: =SUM(C17:J17)+D37+E37+F37+G37-H37 -> 0 | M37: =H37+I37-J37 -> 0
B38: Despesa com Pessoal não Executada Orçamentariamente | D38: =[1]Query_Total!K58 -> 2.030919e+08 | E38: =[1]Query_Total!L58 -> -1.8204937e+08 | F38: =[1]Query_Total!M58 -> -52552996 | G38: =[1]Query_Total!N58 -> -17509338 | H38: =SUM(C18:J18)+D38+E38+F38+G38 -> 0 | J38: =H38+I38 -> 0 | L38: =SUM(C18:J18)+D38+E38+F38+G38-H38 -> -1.1175871e-08 | M38: =H38+I38-J38 -> 0
B39: DESPESAS NÃO COMPUTADAS (II) (§ 1º do art. 19 da LRF) | D39: =SUM(D40:D46) -> 7.9841038e+08 | E39: =SUM(E40:E46) -> 9.3471727e+08 | F39: =SUM(F40:F46) -> 9.6033602e+08 | G39: =SUM(G40:G46) -> 2.0754505e+09 | H39: =SUM(H40:H46) -> 1.1623384e+10 | I39: =SUM(I40:I46) -> 10017.44 | J39: =SUM(J40:J46) -> 1.1623394e+10 | L39: =SUM(C19:J19)+D39+E39+F39+G39-H39 -> 0 | M39: =H39+I39-J39 -> 0
B40: Indenizações por Demissão e Incentivos à Demissão Voluntária | D40: =[1]Query_Total!K62 -> 3142882 | E40: =[1]Query_Total!L62 -> 3366325 | F40: =[1]Query_Total!M62 -> 3785554.6 | G40: =[1]Query_Total!N62 -> 1140691.8 | H40: =SUM(C20:J20)+D40+E40+F40+G40 -> 26034359 | J40: =H40+I40 -> 26034359 | L40: =SUM(C20:J20)+D40+E40+F40+G40-H40 -> 0 | M40: =H40+I40-J40 -> 0
B41: Decorrentes de Decisão Judicial de Período Anterior ao da Apuração | D41: =[1]Query_Total!K65 -> -3088525.3 | E41: =[1]Query_Total!L65 -> 35957642 | F41: =[1]Query_Total!M65 -> 1.4092579e+08 | G41: =[1]Query_Total!N65 -> 3.0221323e+08 | H41: =SUM(C21:J21)+D41+E41+F41+G41 -> 7.1803757e+08 | I41: =[1]Pessoal_3ºQuadrimestre!D62 -> 10017.44 | J41: =H41+I41 -> 7.1804759e+08 | L41: =SUM(C21:J21)+D41+E41+F41+G41-H41 -> 0 | M41: =H41+I41-J41 -> 0
B42: Despesas de Exercícios Anteriores de Período Anterior ao da Apuração | D42: =[1]Query_Total!K74 -> 5119046.5 | E42: =[1]Query_Total!L74 -> 4085395.6 | F42: =[1]Query_Total!M74 -> 14646485 | G42: =[1]Query_Total!N74 -> 14854856 | H42: =SUM(C22:J22)+D42+E42+F42+G42 -> 1.1342713e+08 | J42: =H42+I42 -> 1.1342713e+08 | L42: =SUM(C22:J22)+D42+E42+F42+G42-H42 -> 0 | M42: =H42+I42-J42 -> 0
B43: Inativos e Pensionistas com Recursos Vinculados | D43: =[1]Query_Total!K80 -> 7.9083477e+08 | E43: =[1]Query_Total!L80 -> 8.8898331e+08 | F43: =[1]Query_Total!M80 -> 7.9871748e+08 | G43: =[1]Query_Total!N80 -> 1.7550184e+09 | H43: =SUM(C23:J23)+D43+E43+F43+G43 -> 1.0738114e+10 | I43: 0 | J43: =H43+I43 -> 1.0738114e+10 | L43: =SUM(C23:J23)+D43+E43+F43+G43-H43 -> 0 | M43: =H43+I43-J43 -> 0
...
